<!DOCTYPE html>
<html lang="en">

<head>
    <meta charset="UTF-8">
    <meta http-equiv="X-UA-Compatible" content="IE=edge">
    <meta name="viewport" content="width=device-width, initial-scale=1.0">
    <title>Document</title>
</head>

<body>
    <script>
        /*
        6. promise 异常传透?
        (1) 当使用 promise 的 then 链式调用时, 可以在最后指定失败的回调, 
        (2) 前面任何操作出了异常, 都会传到最后失败的回调中处理

        7. 中断 promise 链?
        (1) 当使用 promise 的 then 链式调用时, 在中间中断, 不再调用后面的回调函数
        (2) 办法: 在回调函数中返回一个 pendding 状态的 promise 对象

        */
        new Promise((resolve, reject) => {
            // resolve(1)
            reject(1)
        }).then(
            value => {
                console.log('onResolved()1', value);
                return 2
            },
            reason => { throw reason }  //(不写也可以，内部默认处理)  失败的结果是逐层传递下去的。
        ).then(
            value => {
                console.log('onResolved()2', value);
                return 3
            },
            reason => { throw reason }
        ).then(
            value => {
                console.log('onResolved()3', value);
            },
            //  => 有返回的作用
            reason => Promise.reject(reason)
        ).catch(
            reason => {
                console.log('onRejected1()', reason);
                // throw reason
                // return Promise.reject(reason)
                return new Promise(() => { }) //返回一个pending的promise  中断promise链
            }
        ).then(
            value => {
                console.log('onResolved()4', value);
            },
            reason => {
                console.log('onRejected()2', reason);
            }
        )
    </script>
</body>

</html>